2025-01-16 15:05:06,175 - alkometer_bot - INFO - TELEGRAM_BOT_TOKEN загружен: Да
2025-01-16 15:05:06,175 - alkometer_bot - INFO - Запуск main()
2025-01-16 15:05:06,175 - alkometer_bot - INFO - Создание приложения бота
2025-01-16 15:05:06,249 - alkometer_bot - INFO - Регистрация обработчиков
2025-01-16 15:05:06,249 - alkometer_bot - INFO - Запуск бота
2025-01-16 15:06:40,168 - alkometer_bot - INFO - Выполняется обработчик /start
2025-01-16 15:06:40,190 - alkometer_bot - ERROR - Exception while handling an update:
Traceback (most recent call last):
  File "/Users/olegrepnikov/Documents/PyCharmProject/alkometer_bot/venv/lib/python3.11/site-packages/sqlalchemy/engine/base.py", line 1964, in _exec_single_context
    self.dialect.do_execute(
  File "/Users/olegrepnikov/Documents/PyCharmProject/alkometer_bot/venv/lib/python3.11/site-packages/sqlalchemy/engine/default.py", line 942, in do_execute
    cursor.execute(statement, parameters)
sqlite3.OperationalError: no such column: users.units

The above exception was the direct cause of the following exception:

Traceback (most recent call last):
  File "/Users/olegrepnikov/Documents/PyCharmProject/alkometer_bot/venv/lib/python3.11/site-packages/telegram/ext/_application.py", line 1325, in process_update
    await coroutine
  File "/Users/olegrepnikov/Documents/PyCharmProject/alkometer_bot/venv/lib/python3.11/site-packages/telegram/ext/_handlers/basehandler.py", line 158, in handle_update
    return await self.callback(update, context)
           ^^^^^^^^^^^^^^^^^^^^^^^^^^^^^^^^^^^^
  File "/Users/olegrepnikov/Documents/PyCharmProject/alkometer_bot/bot/handlers/start.py", line 18, in start
    user = session.query(User).filter(User.telegram_id == user_id).first()
           ^^^^^^^^^^^^^^^^^^^^^^^^^^^^^^^^^^^^^^^^^^^^^^^^^^^^^^^^^^^^^^^
  File "/Users/olegrepnikov/Documents/PyCharmProject/alkometer_bot/venv/lib/python3.11/site-packages/sqlalchemy/orm/query.py", line 2754, in first
    return self.limit(1)._iter().first()  # type: ignore
           ^^^^^^^^^^^^^^^^^^^^^
  File "/Users/olegrepnikov/Documents/PyCharmProject/alkometer_bot/venv/lib/python3.11/site-packages/sqlalchemy/orm/query.py", line 2853, in _iter
    result: Union[ScalarResult[_T], Result[_T]] = self.session.execute(
                                                  ^^^^^^^^^^^^^^^^^^^^^
  File "/Users/olegrepnikov/Documents/PyCharmProject/alkometer_bot/venv/lib/python3.11/site-packages/sqlalchemy/orm/session.py", line 2365, in execute
    return self._execute_internal(
           ^^^^^^^^^^^^^^^^^^^^^^^
  File "/Users/olegrepnikov/Documents/PyCharmProject/alkometer_bot/venv/lib/python3.11/site-packages/sqlalchemy/orm/session.py", line 2251, in _execute_internal
    result: Result[Any] = compile_state_cls.orm_execute_statement(
                          ^^^^^^^^^^^^^^^^^^^^^^^^^^^^^^^^^^^^^^^^
  File "/Users/olegrepnikov/Documents/PyCharmProject/alkometer_bot/venv/lib/python3.11/site-packages/sqlalchemy/orm/context.py", line 305, in orm_execute_statement
    result = conn.execute(
             ^^^^^^^^^^^^^
  File "/Users/olegrepnikov/Documents/PyCharmProject/alkometer_bot/venv/lib/python3.11/site-packages/sqlalchemy/engine/base.py", line 1416, in execute
    return meth(
           ^^^^^
  File "/Users/olegrepnikov/Documents/PyCharmProject/alkometer_bot/venv/lib/python3.11/site-packages/sqlalchemy/sql/elements.py", line 515, in _execute_on_connection
    return connection._execute_clauseelement(
           ^^^^^^^^^^^^^^^^^^^^^^^^^^^^^^^^^^
  File "/Users/olegrepnikov/Documents/PyCharmProject/alkometer_bot/venv/lib/python3.11/site-packages/sqlalchemy/engine/base.py", line 1638, in _execute_clauseelement
    ret = self._execute_context(
          ^^^^^^^^^^^^^^^^^^^^^^
  File "/Users/olegrepnikov/Documents/PyCharmProject/alkometer_bot/venv/lib/python3.11/site-packages/sqlalchemy/engine/base.py", line 1843, in _execute_context
    return self._exec_single_context(
           ^^^^^^^^^^^^^^^^^^^^^^^^^^
  File "/Users/olegrepnikov/Documents/PyCharmProject/alkometer_bot/venv/lib/python3.11/site-packages/sqlalchemy/engine/base.py", line 1983, in _exec_single_context
    self._handle_dbapi_exception(
  File "/Users/olegrepnikov/Documents/PyCharmProject/alkometer_bot/venv/lib/python3.11/site-packages/sqlalchemy/engine/base.py", line 2352, in _handle_dbapi_exception
    raise sqlalchemy_exception.with_traceback(exc_info[2]) from e
  File "/Users/olegrepnikov/Documents/PyCharmProject/alkometer_bot/venv/lib/python3.11/site-packages/sqlalchemy/engine/base.py", line 1964, in _exec_single_context
    self.dialect.do_execute(
  File "/Users/olegrepnikov/Documents/PyCharmProject/alkometer_bot/venv/lib/python3.11/site-packages/sqlalchemy/engine/default.py", line 942, in do_execute
    cursor.execute(statement, parameters)
sqlalchemy.exc.OperationalError: (sqlite3.OperationalError) no such column: users.units
[SQL: SELECT users.id AS users_id, users.telegram_id AS users_telegram_id, users.username AS users_username, users.units AS users_units, users.daily_goal AS users_daily_goal 
FROM users 
WHERE users.telegram_id = ?
 LIMIT ? OFFSET ?]
[parameters: (40791343, 1, 0)]
(Background on this error at: https://sqlalche.me/e/20/e3q8)
2025-01-17 16:43:17,037 - alkometer_bot - INFO - TELEGRAM_BOT_TOKEN загружен: Да
2025-01-17 16:43:17,037 - alkometer_bot - INFO - Запуск main()
2025-01-17 16:43:17,037 - alkometer_bot - INFO - Создание приложения бота
2025-01-17 16:43:17,103 - alkometer_bot - INFO - Регистрация обработчиков
2025-01-17 16:43:17,103 - alkometer_bot - INFO - Запуск бота
2025-01-17 16:43:46,946 - alkometer_bot - INFO - Выполняется обработчик /start
2025-01-17 16:43:51,146 - alkometer_bot - INFO - Пользователь нажал кнопку 'Добавить алкоголь'
2025-01-17 16:44:28,636 - alkometer_bot - INFO - Выполняется обработчик /start
2025-01-17 16:44:31,724 - alkometer_bot - INFO - Выполняется обработчик /report
2025-01-17 16:45:07,486 - alkometer_bot - INFO - TELEGRAM_BOT_TOKEN загружен: Да
2025-01-17 16:45:07,486 - alkometer_bot - INFO - Запуск main()
2025-01-17 16:45:07,486 - alkometer_bot - INFO - Создание приложения бота
2025-01-17 16:45:07,569 - alkometer_bot - INFO - Регистрация обработчиков
2025-01-17 16:45:07,569 - alkometer_bot - INFO - Запуск бота
2025-01-19 14:29:27,011 - alkometer_bot - INFO - TELEGRAM_BOT_TOKEN загружен: Да
2025-01-19 14:29:27,011 - alkometer_bot - INFO - Запуск main()
2025-01-19 14:29:27,011 - alkometer_bot - INFO - Создание приложения бота
2025-01-19 14:29:27,074 - alkometer_bot - INFO - Регистрация обработчиков
2025-01-19 14:29:27,075 - alkometer_bot - INFO - Запуск бота
2025-01-19 14:29:30,867 - alkometer_bot - ERROR - Exception while handling an update:
Traceback (most recent call last):
  File "/Users/olegrepnikov/Documents/PyCharmProject/alkometer_bot/venv/lib/python3.11/site-packages/httpx/_transports/default.py", line 101, in map_httpcore_exceptions
    yield
  File "/Users/olegrepnikov/Documents/PyCharmProject/alkometer_bot/venv/lib/python3.11/site-packages/httpx/_transports/default.py", line 394, in handle_async_request
    resp = await self._pool.handle_async_request(req)
           ^^^^^^^^^^^^^^^^^^^^^^^^^^^^^^^^^^^^^^^^^^
  File "/Users/olegrepnikov/Documents/PyCharmProject/alkometer_bot/venv/lib/python3.11/site-packages/httpcore/_async/connection_pool.py", line 256, in handle_async_request
    raise exc from None
  File "/Users/olegrepnikov/Documents/PyCharmProject/alkometer_bot/venv/lib/python3.11/site-packages/httpcore/_async/connection_pool.py", line 236, in handle_async_request
    response = await connection.handle_async_request(
               ^^^^^^^^^^^^^^^^^^^^^^^^^^^^^^^^^^^^^^
  File "/Users/olegrepnikov/Documents/PyCharmProject/alkometer_bot/venv/lib/python3.11/site-packages/httpcore/_async/connection.py", line 101, in handle_async_request
    raise exc
  File "/Users/olegrepnikov/Documents/PyCharmProject/alkometer_bot/venv/lib/python3.11/site-packages/httpcore/_async/connection.py", line 78, in handle_async_request
    stream = await self._connect(request)
             ^^^^^^^^^^^^^^^^^^^^^^^^^^^^
  File "/Users/olegrepnikov/Documents/PyCharmProject/alkometer_bot/venv/lib/python3.11/site-packages/httpcore/_async/connection.py", line 156, in _connect
    stream = await stream.start_tls(**kwargs)
             ^^^^^^^^^^^^^^^^^^^^^^^^^^^^^^^^
  File "/Users/olegrepnikov/Documents/PyCharmProject/alkometer_bot/venv/lib/python3.11/site-packages/httpcore/_backends/anyio.py", line 67, in start_tls
    with map_exceptions(exc_map):
  File "/Library/Frameworks/Python.framework/Versions/3.11/lib/python3.11/contextlib.py", line 158, in __exit__
    self.gen.throw(typ, value, traceback)
  File "/Users/olegrepnikov/Documents/PyCharmProject/alkometer_bot/venv/lib/python3.11/site-packages/httpcore/_exceptions.py", line 14, in map_exceptions
    raise to_exc(exc) from exc
httpcore.ConnectError

The above exception was the direct cause of the following exception:

Traceback (most recent call last):
  File "/Users/olegrepnikov/Documents/PyCharmProject/alkometer_bot/venv/lib/python3.11/site-packages/telegram/request/_httpxrequest.py", line 293, in do_request
    res = await self._client.request(
          ^^^^^^^^^^^^^^^^^^^^^^^^^^^
  File "/Users/olegrepnikov/Documents/PyCharmProject/alkometer_bot/venv/lib/python3.11/site-packages/httpx/_client.py", line 1540, in request
    return await self.send(request, auth=auth, follow_redirects=follow_redirects)
           ^^^^^^^^^^^^^^^^^^^^^^^^^^^^^^^^^^^^^^^^^^^^^^^^^^^^^^^^^^^^^^^^^^^^^^
  File "/Users/olegrepnikov/Documents/PyCharmProject/alkometer_bot/venv/lib/python3.11/site-packages/httpx/_client.py", line 1629, in send
    response = await self._send_handling_auth(
               ^^^^^^^^^^^^^^^^^^^^^^^^^^^^^^^
  File "/Users/olegrepnikov/Documents/PyCharmProject/alkometer_bot/venv/lib/python3.11/site-packages/httpx/_client.py", line 1657, in _send_handling_auth
    response = await self._send_handling_redirects(
               ^^^^^^^^^^^^^^^^^^^^^^^^^^^^^^^^^^^^
  File "/Users/olegrepnikov/Documents/PyCharmProject/alkometer_bot/venv/lib/python3.11/site-packages/httpx/_client.py", line 1694, in _send_handling_redirects
    response = await self._send_single_request(request)
               ^^^^^^^^^^^^^^^^^^^^^^^^^^^^^^^^^^^^^^^^
  File "/Users/olegrepnikov/Documents/PyCharmProject/alkometer_bot/venv/lib/python3.11/site-packages/httpx/_client.py", line 1730, in _send_single_request
    response = await transport.handle_async_request(request)
               ^^^^^^^^^^^^^^^^^^^^^^^^^^^^^^^^^^^^^^^^^^^^^
  File "/Users/olegrepnikov/Documents/PyCharmProject/alkometer_bot/venv/lib/python3.11/site-packages/httpx/_transports/default.py", line 393, in handle_async_request
    with map_httpcore_exceptions():
  File "/Library/Frameworks/Python.framework/Versions/3.11/lib/python3.11/contextlib.py", line 158, in __exit__
    self.gen.throw(typ, value, traceback)
  File "/Users/olegrepnikov/Documents/PyCharmProject/alkometer_bot/venv/lib/python3.11/site-packages/httpx/_transports/default.py", line 118, in map_httpcore_exceptions
    raise mapped_exc(message) from exc
httpx.ConnectError

The above exception was the direct cause of the following exception:

Traceback (most recent call last):
  File "/Users/olegrepnikov/Documents/PyCharmProject/alkometer_bot/venv/lib/python3.11/site-packages/telegram/ext/_updater.py", line 750, in _network_loop_retry
    if not await do_action():
           ^^^^^^^^^^^^^^^^^
  File "/Users/olegrepnikov/Documents/PyCharmProject/alkometer_bot/venv/lib/python3.11/site-packages/telegram/ext/_updater.py", line 744, in do_action
    return action_cb_task.result()
           ^^^^^^^^^^^^^^^^^^^^^^^
  File "/Users/olegrepnikov/Documents/PyCharmProject/alkometer_bot/venv/lib/python3.11/site-packages/telegram/ext/_updater.py", line 371, in polling_action_cb
    updates = await self.bot.get_updates(
              ^^^^^^^^^^^^^^^^^^^^^^^^^^^
  File "/Users/olegrepnikov/Documents/PyCharmProject/alkometer_bot/venv/lib/python3.11/site-packages/telegram/ext/_extbot.py", line 650, in get_updates
    updates = await super().get_updates(
              ^^^^^^^^^^^^^^^^^^^^^^^^^^
  File "/Users/olegrepnikov/Documents/PyCharmProject/alkometer_bot/venv/lib/python3.11/site-packages/telegram/_bot.py", line 4480, in get_updates
    await self._post(
  File "/Users/olegrepnikov/Documents/PyCharmProject/alkometer_bot/venv/lib/python3.11/site-packages/telegram/_bot.py", line 619, in _post
    return await self._do_post(
           ^^^^^^^^^^^^^^^^^^^^
  File "/Users/olegrepnikov/Documents/PyCharmProject/alkometer_bot/venv/lib/python3.11/site-packages/telegram/ext/_extbot.py", line 354, in _do_post
    return await super()._do_post(
           ^^^^^^^^^^^^^^^^^^^^^^^
  File "/Users/olegrepnikov/Documents/PyCharmProject/alkometer_bot/venv/lib/python3.11/site-packages/telegram/_bot.py", line 648, in _do_post
    result = await request.post(
             ^^^^^^^^^^^^^^^^^^^
  File "/Users/olegrepnikov/Documents/PyCharmProject/alkometer_bot/venv/lib/python3.11/site-packages/telegram/request/_baserequest.py", line 202, in post
    result = await self._request_wrapper(
             ^^^^^^^^^^^^^^^^^^^^^^^^^^^^
  File "/Users/olegrepnikov/Documents/PyCharmProject/alkometer_bot/venv/lib/python3.11/site-packages/telegram/request/_baserequest.py", line 334, in _request_wrapper
    code, payload = await self.do_request(
                    ^^^^^^^^^^^^^^^^^^^^^^
  File "/Users/olegrepnikov/Documents/PyCharmProject/alkometer_bot/venv/lib/python3.11/site-packages/telegram/request/_httpxrequest.py", line 317, in do_request
    raise NetworkError(f"httpx.{err.__class__.__name__}: {err}") from err
telegram.error.NetworkError: httpx.ConnectError: 
2025-01-19 15:42:55,580 - alkometer_bot - INFO - Выполняется обработчик /start
2025-01-19 15:42:59,451 - alkometer_bot - INFO - Пользователь нажал кнопку 'Добавить алкоголь'
2025-01-19 15:43:22,717 - alkometer_bot - INFO - Выполняется обработчик /start
2025-01-19 15:43:24,560 - alkometer_bot - INFO - Выполняется обработчик /report
2025-01-20 04:10:46,619 - alkometer_bot - ERROR - Exception while handling an update:
Traceback (most recent call last):
  File "/Users/olegrepnikov/Documents/PyCharmProject/alkometer_bot/venv/lib/python3.11/site-packages/telegram/ext/_updater.py", line 750, in _network_loop_retry
    if not await do_action():
           ^^^^^^^^^^^^^^^^^
  File "/Users/olegrepnikov/Documents/PyCharmProject/alkometer_bot/venv/lib/python3.11/site-packages/telegram/ext/_updater.py", line 744, in do_action
    return action_cb_task.result()
           ^^^^^^^^^^^^^^^^^^^^^^^
  File "/Users/olegrepnikov/Documents/PyCharmProject/alkometer_bot/venv/lib/python3.11/site-packages/telegram/ext/_updater.py", line 371, in polling_action_cb
    updates = await self.bot.get_updates(
              ^^^^^^^^^^^^^^^^^^^^^^^^^^^
  File "/Users/olegrepnikov/Documents/PyCharmProject/alkometer_bot/venv/lib/python3.11/site-packages/telegram/ext/_extbot.py", line 650, in get_updates
    updates = await super().get_updates(
              ^^^^^^^^^^^^^^^^^^^^^^^^^^
  File "/Users/olegrepnikov/Documents/PyCharmProject/alkometer_bot/venv/lib/python3.11/site-packages/telegram/_bot.py", line 4480, in get_updates
    await self._post(
  File "/Users/olegrepnikov/Documents/PyCharmProject/alkometer_bot/venv/lib/python3.11/site-packages/telegram/_bot.py", line 619, in _post
    return await self._do_post(
           ^^^^^^^^^^^^^^^^^^^^
  File "/Users/olegrepnikov/Documents/PyCharmProject/alkometer_bot/venv/lib/python3.11/site-packages/telegram/ext/_extbot.py", line 354, in _do_post
    return await super()._do_post(
           ^^^^^^^^^^^^^^^^^^^^^^^
  File "/Users/olegrepnikov/Documents/PyCharmProject/alkometer_bot/venv/lib/python3.11/site-packages/telegram/_bot.py", line 648, in _do_post
    result = await request.post(
             ^^^^^^^^^^^^^^^^^^^
  File "/Users/olegrepnikov/Documents/PyCharmProject/alkometer_bot/venv/lib/python3.11/site-packages/telegram/request/_baserequest.py", line 202, in post
    result = await self._request_wrapper(
             ^^^^^^^^^^^^^^^^^^^^^^^^^^^^
  File "/Users/olegrepnikov/Documents/PyCharmProject/alkometer_bot/venv/lib/python3.11/site-packages/telegram/request/_baserequest.py", line 387, in _request_wrapper
    raise NetworkError(description or "Bad Gateway")
telegram.error.NetworkError: Bad Gateway
2025-01-20 12:29:29,573 - alkometer_bot - INFO - TELEGRAM_BOT_TOKEN загружен: Да
2025-01-20 12:29:29,573 - alkometer_bot - INFO - Запуск main()
2025-01-20 12:29:29,573 - alkometer_bot - INFO - Создание приложения бота
2025-01-20 12:29:29,638 - alkometer_bot - INFO - Регистрация обработчиков
2025-01-20 12:29:29,638 - alkometer_bot - INFO - Запуск бота
2025-01-20 12:29:35,892 - alkometer_bot - ERROR - Exception while handling an update:
Traceback (most recent call last):
  File "/Users/olegrepnikov/Documents/PyCharmProject/alkometer_bot/venv/lib/python3.11/site-packages/telegram/ext/_updater.py", line 750, in _network_loop_retry
    if not await do_action():
           ^^^^^^^^^^^^^^^^^
  File "/Users/olegrepnikov/Documents/PyCharmProject/alkometer_bot/venv/lib/python3.11/site-packages/telegram/ext/_updater.py", line 744, in do_action
    return action_cb_task.result()
           ^^^^^^^^^^^^^^^^^^^^^^^
  File "/Users/olegrepnikov/Documents/PyCharmProject/alkometer_bot/venv/lib/python3.11/site-packages/telegram/ext/_updater.py", line 371, in polling_action_cb
    updates = await self.bot.get_updates(
              ^^^^^^^^^^^^^^^^^^^^^^^^^^^
  File "/Users/olegrepnikov/Documents/PyCharmProject/alkometer_bot/venv/lib/python3.11/site-packages/telegram/ext/_extbot.py", line 650, in get_updates
    updates = await super().get_updates(
              ^^^^^^^^^^^^^^^^^^^^^^^^^^
  File "/Users/olegrepnikov/Documents/PyCharmProject/alkometer_bot/venv/lib/python3.11/site-packages/telegram/_bot.py", line 4480, in get_updates
    await self._post(
  File "/Users/olegrepnikov/Documents/PyCharmProject/alkometer_bot/venv/lib/python3.11/site-packages/telegram/_bot.py", line 619, in _post
    return await self._do_post(
           ^^^^^^^^^^^^^^^^^^^^
  File "/Users/olegrepnikov/Documents/PyCharmProject/alkometer_bot/venv/lib/python3.11/site-packages/telegram/ext/_extbot.py", line 354, in _do_post
    return await super()._do_post(
           ^^^^^^^^^^^^^^^^^^^^^^^
  File "/Users/olegrepnikov/Documents/PyCharmProject/alkometer_bot/venv/lib/python3.11/site-packages/telegram/_bot.py", line 648, in _do_post
    result = await request.post(
             ^^^^^^^^^^^^^^^^^^^
  File "/Users/olegrepnikov/Documents/PyCharmProject/alkometer_bot/venv/lib/python3.11/site-packages/telegram/request/_baserequest.py", line 202, in post
    result = await self._request_wrapper(
             ^^^^^^^^^^^^^^^^^^^^^^^^^^^^
  File "/Users/olegrepnikov/Documents/PyCharmProject/alkometer_bot/venv/lib/python3.11/site-packages/telegram/request/_baserequest.py", line 385, in _request_wrapper
    raise Conflict(message)
telegram.error.Conflict: Conflict: terminated by other getUpdates request; make sure that only one bot instance is running
2025-01-20 12:29:41,396 - alkometer_bot - ERROR - Exception while handling an update:
Traceback (most recent call last):
  File "/Users/olegrepnikov/Documents/PyCharmProject/alkometer_bot/venv/lib/python3.11/site-packages/telegram/ext/_updater.py", line 750, in _network_loop_retry
    if not await do_action():
           ^^^^^^^^^^^^^^^^^
  File "/Users/olegrepnikov/Documents/PyCharmProject/alkometer_bot/venv/lib/python3.11/site-packages/telegram/ext/_updater.py", line 744, in do_action
    return action_cb_task.result()
           ^^^^^^^^^^^^^^^^^^^^^^^
  File "/Users/olegrepnikov/Documents/PyCharmProject/alkometer_bot/venv/lib/python3.11/site-packages/telegram/ext/_updater.py", line 371, in polling_action_cb
    updates = await self.bot.get_updates(
              ^^^^^^^^^^^^^^^^^^^^^^^^^^^
  File "/Users/olegrepnikov/Documents/PyCharmProject/alkometer_bot/venv/lib/python3.11/site-packages/telegram/ext/_extbot.py", line 650, in get_updates
    updates = await super().get_updates(
              ^^^^^^^^^^^^^^^^^^^^^^^^^^
  File "/Users/olegrepnikov/Documents/PyCharmProject/alkometer_bot/venv/lib/python3.11/site-packages/telegram/_bot.py", line 4480, in get_updates
    await self._post(
  File "/Users/olegrepnikov/Documents/PyCharmProject/alkometer_bot/venv/lib/python3.11/site-packages/telegram/_bot.py", line 619, in _post
    return await self._do_post(
           ^^^^^^^^^^^^^^^^^^^^
  File "/Users/olegrepnikov/Documents/PyCharmProject/alkometer_bot/venv/lib/python3.11/site-packages/telegram/ext/_extbot.py", line 354, in _do_post
    return await super()._do_post(
           ^^^^^^^^^^^^^^^^^^^^^^^
  File "/Users/olegrepnikov/Documents/PyCharmProject/alkometer_bot/venv/lib/python3.11/site-packages/telegram/_bot.py", line 648, in _do_post
    result = await request.post(
             ^^^^^^^^^^^^^^^^^^^
  File "/Users/olegrepnikov/Documents/PyCharmProject/alkometer_bot/venv/lib/python3.11/site-packages/telegram/request/_baserequest.py", line 202, in post
    result = await self._request_wrapper(
             ^^^^^^^^^^^^^^^^^^^^^^^^^^^^
  File "/Users/olegrepnikov/Documents/PyCharmProject/alkometer_bot/venv/lib/python3.11/site-packages/telegram/request/_baserequest.py", line 385, in _request_wrapper
    raise Conflict(message)
telegram.error.Conflict: Conflict: terminated by other getUpdates request; make sure that only one bot instance is running
2025-01-20 12:29:48,053 - alkometer_bot - ERROR - Exception while handling an update:
Traceback (most recent call last):
  File "/Users/olegrepnikov/Documents/PyCharmProject/alkometer_bot/venv/lib/python3.11/site-packages/telegram/ext/_updater.py", line 750, in _network_loop_retry
    if not await do_action():
           ^^^^^^^^^^^^^^^^^
  File "/Users/olegrepnikov/Documents/PyCharmProject/alkometer_bot/venv/lib/python3.11/site-packages/telegram/ext/_updater.py", line 744, in do_action
    return action_cb_task.result()
           ^^^^^^^^^^^^^^^^^^^^^^^
  File "/Users/olegrepnikov/Documents/PyCharmProject/alkometer_bot/venv/lib/python3.11/site-packages/telegram/ext/_updater.py", line 371, in polling_action_cb
    updates = await self.bot.get_updates(
              ^^^^^^^^^^^^^^^^^^^^^^^^^^^
  File "/Users/olegrepnikov/Documents/PyCharmProject/alkometer_bot/venv/lib/python3.11/site-packages/telegram/ext/_extbot.py", line 650, in get_updates
    updates = await super().get_updates(
              ^^^^^^^^^^^^^^^^^^^^^^^^^^
  File "/Users/olegrepnikov/Documents/PyCharmProject/alkometer_bot/venv/lib/python3.11/site-packages/telegram/_bot.py", line 4480, in get_updates
    await self._post(
  File "/Users/olegrepnikov/Documents/PyCharmProject/alkometer_bot/venv/lib/python3.11/site-packages/telegram/_bot.py", line 619, in _post
    return await self._do_post(
           ^^^^^^^^^^^^^^^^^^^^
  File "/Users/olegrepnikov/Documents/PyCharmProject/alkometer_bot/venv/lib/python3.11/site-packages/telegram/ext/_extbot.py", line 354, in _do_post
    return await super()._do_post(
           ^^^^^^^^^^^^^^^^^^^^^^^
  File "/Users/olegrepnikov/Documents/PyCharmProject/alkometer_bot/venv/lib/python3.11/site-packages/telegram/_bot.py", line 648, in _do_post
    result = await request.post(
             ^^^^^^^^^^^^^^^^^^^
  File "/Users/olegrepnikov/Documents/PyCharmProject/alkometer_bot/venv/lib/python3.11/site-packages/telegram/request/_baserequest.py", line 202, in post
    result = await self._request_wrapper(
             ^^^^^^^^^^^^^^^^^^^^^^^^^^^^
  File "/Users/olegrepnikov/Documents/PyCharmProject/alkometer_bot/venv/lib/python3.11/site-packages/telegram/request/_baserequest.py", line 385, in _request_wrapper
    raise Conflict(message)
telegram.error.Conflict: Conflict: terminated by other getUpdates request; make sure that only one bot instance is running
2025-01-20 12:30:05,274 - alkometer_bot - INFO - TELEGRAM_BOT_TOKEN загружен: Да
2025-01-20 12:30:05,275 - alkometer_bot - INFO - Запуск main()
2025-01-20 12:30:05,275 - alkometer_bot - INFO - Создание приложения бота
2025-01-20 12:30:05,336 - alkometer_bot - INFO - Регистрация обработчиков
2025-01-20 12:30:05,336 - alkometer_bot - INFO - Запуск бота
2025-01-20 12:30:11,539 - alkometer_bot - ERROR - Exception while handling an update:
Traceback (most recent call last):
  File "/Users/olegrepnikov/Documents/PyCharmProject/alkometer_bot/venv/lib/python3.11/site-packages/telegram/ext/_updater.py", line 750, in _network_loop_retry
    if not await do_action():
           ^^^^^^^^^^^^^^^^^
  File "/Users/olegrepnikov/Documents/PyCharmProject/alkometer_bot/venv/lib/python3.11/site-packages/telegram/ext/_updater.py", line 744, in do_action
    return action_cb_task.result()
           ^^^^^^^^^^^^^^^^^^^^^^^
  File "/Users/olegrepnikov/Documents/PyCharmProject/alkometer_bot/venv/lib/python3.11/site-packages/telegram/ext/_updater.py", line 371, in polling_action_cb
    updates = await self.bot.get_updates(
              ^^^^^^^^^^^^^^^^^^^^^^^^^^^
  File "/Users/olegrepnikov/Documents/PyCharmProject/alkometer_bot/venv/lib/python3.11/site-packages/telegram/ext/_extbot.py", line 650, in get_updates
    updates = await super().get_updates(
              ^^^^^^^^^^^^^^^^^^^^^^^^^^
  File "/Users/olegrepnikov/Documents/PyCharmProject/alkometer_bot/venv/lib/python3.11/site-packages/telegram/_bot.py", line 4480, in get_updates
    await self._post(
  File "/Users/olegrepnikov/Documents/PyCharmProject/alkometer_bot/venv/lib/python3.11/site-packages/telegram/_bot.py", line 619, in _post
    return await self._do_post(
           ^^^^^^^^^^^^^^^^^^^^
  File "/Users/olegrepnikov/Documents/PyCharmProject/alkometer_bot/venv/lib/python3.11/site-packages/telegram/ext/_extbot.py", line 354, in _do_post
    return await super()._do_post(
           ^^^^^^^^^^^^^^^^^^^^^^^
  File "/Users/olegrepnikov/Documents/PyCharmProject/alkometer_bot/venv/lib/python3.11/site-packages/telegram/_bot.py", line 648, in _do_post
    result = await request.post(
             ^^^^^^^^^^^^^^^^^^^
  File "/Users/olegrepnikov/Documents/PyCharmProject/alkometer_bot/venv/lib/python3.11/site-packages/telegram/request/_baserequest.py", line 202, in post
    result = await self._request_wrapper(
             ^^^^^^^^^^^^^^^^^^^^^^^^^^^^
  File "/Users/olegrepnikov/Documents/PyCharmProject/alkometer_bot/venv/lib/python3.11/site-packages/telegram/request/_baserequest.py", line 385, in _request_wrapper
    raise Conflict(message)
telegram.error.Conflict: Conflict: terminated by other getUpdates request; make sure that only one bot instance is running
2025-01-20 12:30:16,989 - alkometer_bot - ERROR - Exception while handling an update:
Traceback (most recent call last):
  File "/Users/olegrepnikov/Documents/PyCharmProject/alkometer_bot/venv/lib/python3.11/site-packages/telegram/ext/_updater.py", line 750, in _network_loop_retry
    if not await do_action():
           ^^^^^^^^^^^^^^^^^
  File "/Users/olegrepnikov/Documents/PyCharmProject/alkometer_bot/venv/lib/python3.11/site-packages/telegram/ext/_updater.py", line 744, in do_action
    return action_cb_task.result()
           ^^^^^^^^^^^^^^^^^^^^^^^
  File "/Users/olegrepnikov/Documents/PyCharmProject/alkometer_bot/venv/lib/python3.11/site-packages/telegram/ext/_updater.py", line 371, in polling_action_cb
    updates = await self.bot.get_updates(
              ^^^^^^^^^^^^^^^^^^^^^^^^^^^
  File "/Users/olegrepnikov/Documents/PyCharmProject/alkometer_bot/venv/lib/python3.11/site-packages/telegram/ext/_extbot.py", line 650, in get_updates
    updates = await super().get_updates(
              ^^^^^^^^^^^^^^^^^^^^^^^^^^
  File "/Users/olegrepnikov/Documents/PyCharmProject/alkometer_bot/venv/lib/python3.11/site-packages/telegram/_bot.py", line 4480, in get_updates
    await self._post(
  File "/Users/olegrepnikov/Documents/PyCharmProject/alkometer_bot/venv/lib/python3.11/site-packages/telegram/_bot.py", line 619, in _post
    return await self._do_post(
           ^^^^^^^^^^^^^^^^^^^^
  File "/Users/olegrepnikov/Documents/PyCharmProject/alkometer_bot/venv/lib/python3.11/site-packages/telegram/ext/_extbot.py", line 354, in _do_post
    return await super()._do_post(
           ^^^^^^^^^^^^^^^^^^^^^^^
  File "/Users/olegrepnikov/Documents/PyCharmProject/alkometer_bot/venv/lib/python3.11/site-packages/telegram/_bot.py", line 648, in _do_post
    result = await request.post(
             ^^^^^^^^^^^^^^^^^^^
  File "/Users/olegrepnikov/Documents/PyCharmProject/alkometer_bot/venv/lib/python3.11/site-packages/telegram/request/_baserequest.py", line 202, in post
    result = await self._request_wrapper(
             ^^^^^^^^^^^^^^^^^^^^^^^^^^^^
  File "/Users/olegrepnikov/Documents/PyCharmProject/alkometer_bot/venv/lib/python3.11/site-packages/telegram/request/_baserequest.py", line 385, in _request_wrapper
    raise Conflict(message)
telegram.error.Conflict: Conflict: terminated by other getUpdates request; make sure that only one bot instance is running
2025-01-20 12:30:23,418 - alkometer_bot - ERROR - Exception while handling an update:
Traceback (most recent call last):
  File "/Users/olegrepnikov/Documents/PyCharmProject/alkometer_bot/venv/lib/python3.11/site-packages/telegram/ext/_updater.py", line 750, in _network_loop_retry
    if not await do_action():
           ^^^^^^^^^^^^^^^^^
  File "/Users/olegrepnikov/Documents/PyCharmProject/alkometer_bot/venv/lib/python3.11/site-packages/telegram/ext/_updater.py", line 744, in do_action
    return action_cb_task.result()
           ^^^^^^^^^^^^^^^^^^^^^^^
  File "/Users/olegrepnikov/Documents/PyCharmProject/alkometer_bot/venv/lib/python3.11/site-packages/telegram/ext/_updater.py", line 371, in polling_action_cb
    updates = await self.bot.get_updates(
              ^^^^^^^^^^^^^^^^^^^^^^^^^^^
  File "/Users/olegrepnikov/Documents/PyCharmProject/alkometer_bot/venv/lib/python3.11/site-packages/telegram/ext/_extbot.py", line 650, in get_updates
    updates = await super().get_updates(
              ^^^^^^^^^^^^^^^^^^^^^^^^^^
  File "/Users/olegrepnikov/Documents/PyCharmProject/alkometer_bot/venv/lib/python3.11/site-packages/telegram/_bot.py", line 4480, in get_updates
    await self._post(
  File "/Users/olegrepnikov/Documents/PyCharmProject/alkometer_bot/venv/lib/python3.11/site-packages/telegram/_bot.py", line 619, in _post
    return await self._do_post(
           ^^^^^^^^^^^^^^^^^^^^
  File "/Users/olegrepnikov/Documents/PyCharmProject/alkometer_bot/venv/lib/python3.11/site-packages/telegram/ext/_extbot.py", line 354, in _do_post
    return await super()._do_post(
           ^^^^^^^^^^^^^^^^^^^^^^^
  File "/Users/olegrepnikov/Documents/PyCharmProject/alkometer_bot/venv/lib/python3.11/site-packages/telegram/_bot.py", line 648, in _do_post
    result = await request.post(
             ^^^^^^^^^^^^^^^^^^^
  File "/Users/olegrepnikov/Documents/PyCharmProject/alkometer_bot/venv/lib/python3.11/site-packages/telegram/request/_baserequest.py", line 202, in post
    result = await self._request_wrapper(
             ^^^^^^^^^^^^^^^^^^^^^^^^^^^^
  File "/Users/olegrepnikov/Documents/PyCharmProject/alkometer_bot/venv/lib/python3.11/site-packages/telegram/request/_baserequest.py", line 385, in _request_wrapper
    raise Conflict(message)
telegram.error.Conflict: Conflict: terminated by other getUpdates request; make sure that only one bot instance is running
2025-01-20 12:30:31,345 - alkometer_bot - ERROR - Exception while handling an update:
Traceback (most recent call last):
  File "/Users/olegrepnikov/Documents/PyCharmProject/alkometer_bot/venv/lib/python3.11/site-packages/telegram/ext/_updater.py", line 750, in _network_loop_retry
    if not await do_action():
           ^^^^^^^^^^^^^^^^^
  File "/Users/olegrepnikov/Documents/PyCharmProject/alkometer_bot/venv/lib/python3.11/site-packages/telegram/ext/_updater.py", line 744, in do_action
    return action_cb_task.result()
           ^^^^^^^^^^^^^^^^^^^^^^^
  File "/Users/olegrepnikov/Documents/PyCharmProject/alkometer_bot/venv/lib/python3.11/site-packages/telegram/ext/_updater.py", line 371, in polling_action_cb
    updates = await self.bot.get_updates(
              ^^^^^^^^^^^^^^^^^^^^^^^^^^^
  File "/Users/olegrepnikov/Documents/PyCharmProject/alkometer_bot/venv/lib/python3.11/site-packages/telegram/ext/_extbot.py", line 650, in get_updates
    updates = await super().get_updates(
              ^^^^^^^^^^^^^^^^^^^^^^^^^^
  File "/Users/olegrepnikov/Documents/PyCharmProject/alkometer_bot/venv/lib/python3.11/site-packages/telegram/_bot.py", line 4480, in get_updates
    await self._post(
  File "/Users/olegrepnikov/Documents/PyCharmProject/alkometer_bot/venv/lib/python3.11/site-packages/telegram/_bot.py", line 619, in _post
    return await self._do_post(
           ^^^^^^^^^^^^^^^^^^^^
  File "/Users/olegrepnikov/Documents/PyCharmProject/alkometer_bot/venv/lib/python3.11/site-packages/telegram/ext/_extbot.py", line 354, in _do_post
    return await super()._do_post(
           ^^^^^^^^^^^^^^^^^^^^^^^
  File "/Users/olegrepnikov/Documents/PyCharmProject/alkometer_bot/venv/lib/python3.11/site-packages/telegram/_bot.py", line 648, in _do_post
    result = await request.post(
             ^^^^^^^^^^^^^^^^^^^
  File "/Users/olegrepnikov/Documents/PyCharmProject/alkometer_bot/venv/lib/python3.11/site-packages/telegram/request/_baserequest.py", line 202, in post
    result = await self._request_wrapper(
             ^^^^^^^^^^^^^^^^^^^^^^^^^^^^
  File "/Users/olegrepnikov/Documents/PyCharmProject/alkometer_bot/venv/lib/python3.11/site-packages/telegram/request/_baserequest.py", line 385, in _request_wrapper
    raise Conflict(message)
telegram.error.Conflict: Conflict: terminated by other getUpdates request; make sure that only one bot instance is running
2025-01-20 12:30:38,529 - alkometer_bot - ERROR - Exception while handling an update:
Traceback (most recent call last):
  File "/Users/olegrepnikov/Documents/PyCharmProject/alkometer_bot/venv/lib/python3.11/site-packages/telegram/ext/_updater.py", line 750, in _network_loop_retry
    if not await do_action():
           ^^^^^^^^^^^^^^^^^
  File "/Users/olegrepnikov/Documents/PyCharmProject/alkometer_bot/venv/lib/python3.11/site-packages/telegram/ext/_updater.py", line 744, in do_action
    return action_cb_task.result()
           ^^^^^^^^^^^^^^^^^^^^^^^
  File "/Users/olegrepnikov/Documents/PyCharmProject/alkometer_bot/venv/lib/python3.11/site-packages/telegram/ext/_updater.py", line 371, in polling_action_cb
    updates = await self.bot.get_updates(
              ^^^^^^^^^^^^^^^^^^^^^^^^^^^
  File "/Users/olegrepnikov/Documents/PyCharmProject/alkometer_bot/venv/lib/python3.11/site-packages/telegram/ext/_extbot.py", line 650, in get_updates
    updates = await super().get_updates(
              ^^^^^^^^^^^^^^^^^^^^^^^^^^
  File "/Users/olegrepnikov/Documents/PyCharmProject/alkometer_bot/venv/lib/python3.11/site-packages/telegram/_bot.py", line 4480, in get_updates
    await self._post(
  File "/Users/olegrepnikov/Documents/PyCharmProject/alkometer_bot/venv/lib/python3.11/site-packages/telegram/_bot.py", line 619, in _post
    return await self._do_post(
           ^^^^^^^^^^^^^^^^^^^^
  File "/Users/olegrepnikov/Documents/PyCharmProject/alkometer_bot/venv/lib/python3.11/site-packages/telegram/ext/_extbot.py", line 354, in _do_post
    return await super()._do_post(
           ^^^^^^^^^^^^^^^^^^^^^^^
  File "/Users/olegrepnikov/Documents/PyCharmProject/alkometer_bot/venv/lib/python3.11/site-packages/telegram/_bot.py", line 648, in _do_post
    result = await request.post(
             ^^^^^^^^^^^^^^^^^^^
  File "/Users/olegrepnikov/Documents/PyCharmProject/alkometer_bot/venv/lib/python3.11/site-packages/telegram/request/_baserequest.py", line 202, in post
    result = await self._request_wrapper(
             ^^^^^^^^^^^^^^^^^^^^^^^^^^^^
  File "/Users/olegrepnikov/Documents/PyCharmProject/alkometer_bot/venv/lib/python3.11/site-packages/telegram/request/_baserequest.py", line 385, in _request_wrapper
    raise Conflict(message)
telegram.error.Conflict: Conflict: terminated by other getUpdates request; make sure that only one bot instance is running
